
# [CVE-2010-3495](http://bugs.python.org/issue6706)

## Description

- `Race condition in ZEO/StorageServer.py in Zope Object Database (ZODB) before 3.10.0 allows remote attackers to cause a denial of service (daemon outage) by establishing and then immediately closing a TCP connection, leading to the accept function having an unexpected return value of None, an unexpected value of None for the address, or an ECONNABORTED, EAGAIN, or EWOULDBLOCK error, a related issue to CVE-2010-3492.`

## Cvss Data

- **Access Vector**:
  - NETWORK
- **Base Score**:
  - 4.3

## Scores

- **Exploitability Score**:
  - 8.6
- **Impact Score**:
  - 2.9
- **Base Severity**:
  - MEDIUM

## Other Information

- **Publish Date**:
  - 2010-10-19 20:00:04
- **Vulnerability Status**:
  - Modified

## References

- **cve@mitre.org**: http://bugs.python.org/issue6706
- **cve@mitre.org**: http://lists.opensuse.org/opensuse-security-announce/2010-12/msg00006.html
- **cve@mitre.org**: http://pypi.python.org/pypi/ZODB3/3.10.0#id1
- **cve@mitre.org**: http://secunia.com/advisories/41755
- **cve@mitre.org**: http://www.openwall.com/lists/oss-security/2010/09/09/6
- **cve@mitre.org**: http://www.openwall.com/lists/oss-security/2010/09/11/2
- **cve@mitre.org**: http://www.openwall.com/lists/oss-security/2010/09/22/3
- **cve@mitre.org**: http://www.openwall.com/lists/oss-security/2010/09/24/3
- **cve@mitre.org**: https://bugs.launchpad.net/zodb/+bug/135108
